<?xml version="1.0" encoding="UTF-8"?>
<!-- Generated by org.testng.reporters.JUnitReportReporter -->
<testsuite hostname="Dooby" failures="0" tests="1" name="com.dooby.testCases.BankManagerLoginTest" time="0.376" errors="1" timestamp="2021-04-03T15:31:17 IST" skipped="0">
  <testcase classname="com.dooby.testCases.BankManagerLoginTest" name="bankManagerLoginTest" time="0.376">
    <error message="Cannot invoke &quot;com.relevantcodes.extentreports.ExtentTest.log(com.relevantcodes.extentreports.LogStatus, String)&quot; because &quot;com.dooby.base.TestBase.test&quot; is null" type="java.lang.NullPointerException">
      <![CDATA[java.lang.NullPointerException: Cannot invoke "com.relevantcodes.extentreports.ExtentTest.log(com.relevantcodes.extentreports.LogStatus, String)" because "com.dooby.base.TestBase.test" is null
at com.dooby.base.TestBase.verifyEquals(TestBase.java:233)
at com.dooby.testCases.BankManagerLoginTest.bankManagerLoginTest(BankManagerLoginTest.java:18)
at java.base/jdk.internal.reflect.NativeMethodAccessorImpl.invoke0(Native Method)
at java.base/jdk.internal.reflect.NativeMethodAccessorImpl.invoke(NativeMethodAccessorImpl.java:64)
at java.base/jdk.internal.reflect.DelegatingMethodAccessorImpl.invoke(DelegatingMethodAccessorImpl.java:43)
at java.base/java.lang.reflect.Method.invoke(Method.java:564)
at org.testng.internal.MethodInvocationHelper.invokeMethod(MethodInvocationHelper.java:132)
at org.testng.internal.TestInvoker.invokeMethod(TestInvoker.java:599)
at org.testng.internal.TestInvoker.invokeTestMethod(TestInvoker.java:174)
at org.testng.internal.MethodRunner.runInSequence(MethodRunner.java:46)
at org.testng.internal.TestInvoker$MethodInvocationAgent.invoke(TestInvoker.java:822)
at org.testng.internal.TestInvoker.invokeTestMethods(TestInvoker.java:147)
at org.testng.internal.TestMethodWorker.invokeTestMethods(TestMethodWorker.java:146)
at org.testng.internal.TestMethodWorker.run(TestMethodWorker.java:128)
at java.base/java.util.ArrayList.forEach(ArrayList.java:1511)
at org.testng.TestRunner.privateRun(TestRunner.java:764)
at org.testng.TestRunner.run(TestRunner.java:585)
at org.testng.SuiteRunner.runTest(SuiteRunner.java:384)
at org.testng.SuiteRunner.runSequentially(SuiteRunner.java:378)
at org.testng.SuiteRunner.privateRun(SuiteRunner.java:337)
at org.testng.SuiteRunner.run(SuiteRunner.java:286)
at org.testng.SuiteRunnerWorker.runSuite(SuiteRunnerWorker.java:53)
at org.testng.SuiteRunnerWorker.run(SuiteRunnerWorker.java:96)
at org.testng.TestNG.runSuitesSequentially(TestNG.java:1218)
at org.testng.TestNG.runSuitesLocally(TestNG.java:1140)
at org.testng.TestNG.runSuites(TestNG.java:1069)
at org.testng.TestNG.run(TestNG.java:1037)
at org.testng.remote.AbstractRemoteTestNG.run(AbstractRemoteTestNG.java:115)
at org.testng.remote.RemoteTestNG.initAndRun(RemoteTestNG.java:251)
at org.testng.remote.RemoteTestNG.main(RemoteTestNG.java:77)
]]>
    </error>
  </testcase> <!-- bankManagerLoginTest -->
  <system-out>
Click to see the Screenshot <br>Verification Failure: expected [xyx] but found [yzy]<br> <a target="_blank" href=C:\Users\Dooby\eclipse-workspace\Final-Projects\DataDrivenFramework\target\surefire-reports\html\Protractor_practice_website_-_Banking_AppSat_Apr_03_15_31_16_IST_2021.jpg><img src=C:\Users\Dooby\eclipse-workspace\Final-Projects\DataDrivenFramework\target\surefire-reports\html\Protractor_practice_website_-_Banking_AppSat_Apr_03_15_31_16_IST_2021.jpg height = 400 width = 600></img></a> <br> <br>  </system-out>
</testsuite> <!-- com.dooby.testCases.BankManagerLoginTest -->
